[2023-12-19 10:49:44,045] [autoreload.py:677] [autoreload:run_with_reloader] [INFO]- Watching for file changes with StatReloader
[2023-12-19 10:52:05,948] [basehttp.py:187] [basehttp:log_message] [INFO]- "POST /group/login HTTP/1.1" 200 131
[2023-12-19 10:52:14,562] [log.py:241] [log:log_response] [WARNING]- Not Found: /group/case/sprintlist
[2023-12-19 10:52:14,562] [basehttp.py:187] [basehttp:log_message] [WARNING]- "POST /group/case/sprintlist HTTP/1.1" 404 3098
[2023-12-19 10:52:19,991] [log.py:241] [log:log_response] [WARNING]- Not Found: /group/case/sprintlist
[2023-12-19 10:52:19,992] [basehttp.py:187] [basehttp:log_message] [WARNING]- "POST /group/case/sprintlist HTTP/1.1" 404 3098
[2023-12-19 10:53:36,540] [log.py:241] [log:log_response] [WARNING]- Not Found: /group/case/sprintlist
[2023-12-19 10:53:36,541] [basehttp.py:187] [basehttp:log_message] [WARNING]- "POST /group/case/sprintlist HTTP/1.1" 404 3098
[2023-12-19 10:55:13,822] [log.py:241] [log:log_response] [WARNING]- Forbidden: /case/sprintlist
[2023-12-19 10:55:13,824] [basehttp.py:187] [basehttp:log_message] [WARNING]- "POST /case/sprintlist HTTP/1.1" 403 28
[2023-12-19 11:07:44,236] [log.py:241] [log:log_response] [WARNING]- Forbidden: /case/sprintlist
[2023-12-19 11:07:44,237] [basehttp.py:187] [basehttp:log_message] [WARNING]- "POST /case/sprintlist HTTP/1.1" 403 28
[2023-12-19 11:08:15,699] [basehttp.py:187] [basehttp:log_message] [INFO]- "POST /case/sprintlist HTTP/1.1" 200 46
[2023-12-19 11:50:00,495] [autoreload.py:677] [autoreload:run_with_reloader] [INFO]- Watching for file changes with StatReloader
[2023-12-19 11:50:10,219] [basehttp.py:187] [basehttp:log_message] [INFO]- "POST /group/login HTTP/1.1" 200 136
[2023-12-19 12:01:57,020] [basehttp.py:187] [basehttp:log_message] [INFO]- "OPTIONS /case/sprintlist HTTP/1.1" 200 0
[2023-12-19 12:01:57,038] [basehttp.py:187] [basehttp:log_message] [INFO]- "POST /case/sprintlist HTTP/1.1" 200 46
[2023-12-19 12:01:57,872] [basehttp.py:187] [basehttp:log_message] [INFO]- "POST /case/sprintlist HTTP/1.1" 200 46
[2023-12-19 12:02:02,247] [basehttp.py:187] [basehttp:log_message] [INFO]- "OPTIONS /case/createsprint HTTP/1.1" 200 0
[2023-12-19 12:02:02,361] [log.py:241] [log:log_response] [ERROR]- Internal Server Error: /case/createsprint
Traceback (most recent call last):
  File "/Users/yehl/Documents/软件测试资料/softwarebox/lib/python3.10/site-packages/django/db/backends/utils.py", line 89, in _execute
    return self.cursor.execute(sql, params)
  File "/Users/yehl/Documents/软件测试资料/softwarebox/lib/python3.10/site-packages/django/db/backends/mysql/base.py", line 75, in execute
    return self.cursor.execute(query, args)
  File "/Users/yehl/Documents/软件测试资料/softwarebox/lib/python3.10/site-packages/pymysql/cursors.py", line 148, in execute
    result = self._query(query)
  File "/Users/yehl/Documents/软件测试资料/softwarebox/lib/python3.10/site-packages/pymysql/cursors.py", line 310, in _query
    conn.query(q)
  File "/Users/yehl/Documents/软件测试资料/softwarebox/lib/python3.10/site-packages/pymysql/connections.py", line 548, in query
    self._affected_rows = self._read_query_result(unbuffered=unbuffered)
  File "/Users/yehl/Documents/软件测试资料/softwarebox/lib/python3.10/site-packages/pymysql/connections.py", line 775, in _read_query_result
    result.read()
  File "/Users/yehl/Documents/软件测试资料/softwarebox/lib/python3.10/site-packages/pymysql/connections.py", line 1156, in read
    first_packet = self.connection._read_packet()
  File "/Users/yehl/Documents/软件测试资料/softwarebox/lib/python3.10/site-packages/pymysql/connections.py", line 725, in _read_packet
    packet.raise_for_error()
  File "/Users/yehl/Documents/软件测试资料/softwarebox/lib/python3.10/site-packages/pymysql/protocol.py", line 221, in raise_for_error
    err.raise_mysql_exception(self._data)
  File "/Users/yehl/Documents/软件测试资料/softwarebox/lib/python3.10/site-packages/pymysql/err.py", line 143, in raise_mysql_exception
    raise errorclass(errno, errval)
pymysql.err.ProgrammingError: (1146, "Table 'testplatform.apiauto_apiauto' doesn't exist")

The above exception was the direct cause of the following exception:

Traceback (most recent call last):
  File "/Users/yehl/Documents/软件测试资料/softwarebox/lib/python3.10/site-packages/django/core/handlers/exception.py", line 55, in inner
    response = get_response(request)
  File "/Users/yehl/Documents/软件测试资料/softwarebox/lib/python3.10/site-packages/django/core/handlers/base.py", line 197, in _get_response
    response = wrapped_callback(request, *callback_args, **callback_kwargs)
  File "/Users/yehl/Documents/软件测试资料/softwarebox/lib/python3.10/site-packages/django/views/decorators/csrf.py", line 54, in wrapped_view
    return view_func(*args, **kwargs)
  File "/Users/yehl/Documents/软件测试资料/softwarebox/lib/python3.10/site-packages/django/views/generic/base.py", line 84, in view
    return self.dispatch(request, *args, **kwargs)
  File "/Users/yehl/Documents/软件测试资料/softwarebox/lib/python3.10/site-packages/rest_framework/views.py", line 509, in dispatch
    response = self.handle_exception(exc)
  File "/Users/yehl/Documents/软件测试资料/softwarebox/lib/python3.10/site-packages/rest_framework/views.py", line 469, in handle_exception
    self.raise_uncaught_exception(exc)
  File "/Users/yehl/Documents/软件测试资料/softwarebox/lib/python3.10/site-packages/rest_framework/views.py", line 480, in raise_uncaught_exception
    raise exc
  File "/Users/yehl/Documents/软件测试资料/softwarebox/lib/python3.10/site-packages/rest_framework/views.py", line 506, in dispatch
    response = handler(request, *args, **kwargs)
  File "/Users/yehl/Documents/testPlaform/TPlatform/SprintList/views.py", line 36, in delete
    sprints.objects.get(sprint_name=sprint_name).delete()
  File "/Users/yehl/Documents/软件测试资料/softwarebox/lib/python3.10/site-packages/django/db/models/base.py", line 1094, in delete
    return collector.delete()
  File "/Users/yehl/Documents/软件测试资料/softwarebox/lib/python3.10/site-packages/django/db/models/deletion.py", line 462, in delete
    count = qs._raw_delete(using=self.using)
  File "/Users/yehl/Documents/软件测试资料/softwarebox/lib/python3.10/site-packages/django/db/models/query.py", line 843, in _raw_delete
    cursor = query.get_compiler(using).execute_sql(CURSOR)
  File "/Users/yehl/Documents/软件测试资料/softwarebox/lib/python3.10/site-packages/django/db/models/sql/compiler.py", line 1361, in execute_sql
    cursor.execute(sql, params)
  File "/Users/yehl/Documents/软件测试资料/softwarebox/lib/python3.10/site-packages/django/db/backends/utils.py", line 103, in execute
    return super().execute(sql, params)
  File "/Users/yehl/Documents/软件测试资料/softwarebox/lib/python3.10/site-packages/django/db/backends/utils.py", line 67, in execute
    return self._execute_with_wrappers(
  File "/Users/yehl/Documents/软件测试资料/softwarebox/lib/python3.10/site-packages/django/db/backends/utils.py", line 80, in _execute_with_wrappers
    return executor(sql, params, many, context)
  File "/Users/yehl/Documents/软件测试资料/softwarebox/lib/python3.10/site-packages/django/db/backends/utils.py", line 84, in _execute
    with self.db.wrap_database_errors:
  File "/Users/yehl/Documents/软件测试资料/softwarebox/lib/python3.10/site-packages/django/db/utils.py", line 91, in __exit__
    raise dj_exc_value.with_traceback(traceback) from exc_value
  File "/Users/yehl/Documents/软件测试资料/softwarebox/lib/python3.10/site-packages/django/db/backends/utils.py", line 89, in _execute
    return self.cursor.execute(sql, params)
  File "/Users/yehl/Documents/软件测试资料/softwarebox/lib/python3.10/site-packages/django/db/backends/mysql/base.py", line 75, in execute
    return self.cursor.execute(query, args)
  File "/Users/yehl/Documents/软件测试资料/softwarebox/lib/python3.10/site-packages/pymysql/cursors.py", line 148, in execute
    result = self._query(query)
  File "/Users/yehl/Documents/软件测试资料/softwarebox/lib/python3.10/site-packages/pymysql/cursors.py", line 310, in _query
    conn.query(q)
  File "/Users/yehl/Documents/软件测试资料/softwarebox/lib/python3.10/site-packages/pymysql/connections.py", line 548, in query
    self._affected_rows = self._read_query_result(unbuffered=unbuffered)
  File "/Users/yehl/Documents/软件测试资料/softwarebox/lib/python3.10/site-packages/pymysql/connections.py", line 775, in _read_query_result
    result.read()
  File "/Users/yehl/Documents/软件测试资料/softwarebox/lib/python3.10/site-packages/pymysql/connections.py", line 1156, in read
    first_packet = self.connection._read_packet()
  File "/Users/yehl/Documents/软件测试资料/softwarebox/lib/python3.10/site-packages/pymysql/connections.py", line 725, in _read_packet
    packet.raise_for_error()
  File "/Users/yehl/Documents/软件测试资料/softwarebox/lib/python3.10/site-packages/pymysql/protocol.py", line 221, in raise_for_error
    err.raise_mysql_exception(self._data)
  File "/Users/yehl/Documents/软件测试资料/softwarebox/lib/python3.10/site-packages/pymysql/err.py", line 143, in raise_mysql_exception
    raise errorclass(errno, errval)
django.db.utils.ProgrammingError: (1146, "Table 'testplatform.apiauto_apiauto' doesn't exist")
[2023-12-19 12:02:02,416] [basehttp.py:187] [basehttp:log_message] [ERROR]- "DELETE /case/createsprint HTTP/1.1" 500 210291
[2023-12-19 12:02:05,956] [basehttp.py:187] [basehttp:log_message] [INFO]- "POST /case/sprintlist HTTP/1.1" 200 46
[2023-12-19 12:02:06,853] [basehttp.py:187] [basehttp:log_message] [INFO]- "POST /case/sprintlist HTTP/1.1" 200 46
[2023-12-19 12:02:16,268] [basehttp.py:187] [basehttp:log_message] [INFO]- "POST /case/sprintlist HTTP/1.1" 200 46
[2023-12-19 12:02:20,011] [log.py:241] [log:log_response] [ERROR]- Internal Server Error: /case/createsprint
Traceback (most recent call last):
  File "/Users/yehl/Documents/软件测试资料/softwarebox/lib/python3.10/site-packages/django/db/backends/utils.py", line 89, in _execute
    return self.cursor.execute(sql, params)
  File "/Users/yehl/Documents/软件测试资料/softwarebox/lib/python3.10/site-packages/django/db/backends/mysql/base.py", line 75, in execute
    return self.cursor.execute(query, args)
  File "/Users/yehl/Documents/软件测试资料/softwarebox/lib/python3.10/site-packages/pymysql/cursors.py", line 148, in execute
    result = self._query(query)
  File "/Users/yehl/Documents/软件测试资料/softwarebox/lib/python3.10/site-packages/pymysql/cursors.py", line 310, in _query
    conn.query(q)
  File "/Users/yehl/Documents/软件测试资料/softwarebox/lib/python3.10/site-packages/pymysql/connections.py", line 548, in query
    self._affected_rows = self._read_query_result(unbuffered=unbuffered)
  File "/Users/yehl/Documents/软件测试资料/softwarebox/lib/python3.10/site-packages/pymysql/connections.py", line 775, in _read_query_result
    result.read()
  File "/Users/yehl/Documents/软件测试资料/softwarebox/lib/python3.10/site-packages/pymysql/connections.py", line 1156, in read
    first_packet = self.connection._read_packet()
  File "/Users/yehl/Documents/软件测试资料/softwarebox/lib/python3.10/site-packages/pymysql/connections.py", line 725, in _read_packet
    packet.raise_for_error()
  File "/Users/yehl/Documents/软件测试资料/softwarebox/lib/python3.10/site-packages/pymysql/protocol.py", line 221, in raise_for_error
    err.raise_mysql_exception(self._data)
  File "/Users/yehl/Documents/软件测试资料/softwarebox/lib/python3.10/site-packages/pymysql/err.py", line 143, in raise_mysql_exception
    raise errorclass(errno, errval)
pymysql.err.ProgrammingError: (1146, "Table 'testplatform.apiauto_apiauto' doesn't exist")

The above exception was the direct cause of the following exception:

Traceback (most recent call last):
  File "/Users/yehl/Documents/软件测试资料/softwarebox/lib/python3.10/site-packages/django/core/handlers/exception.py", line 55, in inner
    response = get_response(request)
  File "/Users/yehl/Documents/软件测试资料/softwarebox/lib/python3.10/site-packages/django/core/handlers/base.py", line 197, in _get_response
    response = wrapped_callback(request, *callback_args, **callback_kwargs)
  File "/Users/yehl/Documents/软件测试资料/softwarebox/lib/python3.10/site-packages/django/views/decorators/csrf.py", line 54, in wrapped_view
    return view_func(*args, **kwargs)
  File "/Users/yehl/Documents/软件测试资料/softwarebox/lib/python3.10/site-packages/django/views/generic/base.py", line 84, in view
    return self.dispatch(request, *args, **kwargs)
  File "/Users/yehl/Documents/软件测试资料/softwarebox/lib/python3.10/site-packages/rest_framework/views.py", line 509, in dispatch
    response = self.handle_exception(exc)
  File "/Users/yehl/Documents/软件测试资料/softwarebox/lib/python3.10/site-packages/rest_framework/views.py", line 469, in handle_exception
    self.raise_uncaught_exception(exc)
  File "/Users/yehl/Documents/软件测试资料/softwarebox/lib/python3.10/site-packages/rest_framework/views.py", line 480, in raise_uncaught_exception
    raise exc
  File "/Users/yehl/Documents/软件测试资料/softwarebox/lib/python3.10/site-packages/rest_framework/views.py", line 506, in dispatch
    response = handler(request, *args, **kwargs)
  File "/Users/yehl/Documents/testPlaform/TPlatform/SprintList/views.py", line 36, in delete
    sprints.objects.get(sprint_name=sprint_name).delete()
  File "/Users/yehl/Documents/软件测试资料/softwarebox/lib/python3.10/site-packages/django/db/models/base.py", line 1094, in delete
    return collector.delete()
  File "/Users/yehl/Documents/软件测试资料/softwarebox/lib/python3.10/site-packages/django/db/models/deletion.py", line 462, in delete
    count = qs._raw_delete(using=self.using)
  File "/Users/yehl/Documents/软件测试资料/softwarebox/lib/python3.10/site-packages/django/db/models/query.py", line 843, in _raw_delete
    cursor = query.get_compiler(using).execute_sql(CURSOR)
  File "/Users/yehl/Documents/软件测试资料/softwarebox/lib/python3.10/site-packages/django/db/models/sql/compiler.py", line 1361, in execute_sql
    cursor.execute(sql, params)
  File "/Users/yehl/Documents/软件测试资料/softwarebox/lib/python3.10/site-packages/django/db/backends/utils.py", line 103, in execute
    return super().execute(sql, params)
  File "/Users/yehl/Documents/软件测试资料/softwarebox/lib/python3.10/site-packages/django/db/backends/utils.py", line 67, in execute
    return self._execute_with_wrappers(
  File "/Users/yehl/Documents/软件测试资料/softwarebox/lib/python3.10/site-packages/django/db/backends/utils.py", line 80, in _execute_with_wrappers
    return executor(sql, params, many, context)
  File "/Users/yehl/Documents/软件测试资料/softwarebox/lib/python3.10/site-packages/django/db/backends/utils.py", line 84, in _execute
    with self.db.wrap_database_errors:
  File "/Users/yehl/Documents/软件测试资料/softwarebox/lib/python3.10/site-packages/django/db/utils.py", line 91, in __exit__
    raise dj_exc_value.with_traceback(traceback) from exc_value
  File "/Users/yehl/Documents/软件测试资料/softwarebox/lib/python3.10/site-packages/django/db/backends/utils.py", line 89, in _execute
    return self.cursor.execute(sql, params)
  File "/Users/yehl/Documents/软件测试资料/softwarebox/lib/python3.10/site-packages/django/db/backends/mysql/base.py", line 75, in execute
    return self.cursor.execute(query, args)
  File "/Users/yehl/Documents/软件测试资料/softwarebox/lib/python3.10/site-packages/pymysql/cursors.py", line 148, in execute
    result = self._query(query)
  File "/Users/yehl/Documents/软件测试资料/softwarebox/lib/python3.10/site-packages/pymysql/cursors.py", line 310, in _query
    conn.query(q)
  File "/Users/yehl/Documents/软件测试资料/softwarebox/lib/python3.10/site-packages/pymysql/connections.py", line 548, in query
    self._affected_rows = self._read_query_result(unbuffered=unbuffered)
  File "/Users/yehl/Documents/软件测试资料/softwarebox/lib/python3.10/site-packages/pymysql/connections.py", line 775, in _read_query_result
    result.read()
  File "/Users/yehl/Documents/软件测试资料/softwarebox/lib/python3.10/site-packages/pymysql/connections.py", line 1156, in read
    first_packet = self.connection._read_packet()
  File "/Users/yehl/Documents/软件测试资料/softwarebox/lib/python3.10/site-packages/pymysql/connections.py", line 725, in _read_packet
    packet.raise_for_error()
  File "/Users/yehl/Documents/软件测试资料/softwarebox/lib/python3.10/site-packages/pymysql/protocol.py", line 221, in raise_for_error
    err.raise_mysql_exception(self._data)
  File "/Users/yehl/Documents/软件测试资料/softwarebox/lib/python3.10/site-packages/pymysql/err.py", line 143, in raise_mysql_exception
    raise errorclass(errno, errval)
django.db.utils.ProgrammingError: (1146, "Table 'testplatform.apiauto_apiauto' doesn't exist")
[2023-12-19 12:02:20,020] [basehttp.py:187] [basehttp:log_message] [ERROR]- "DELETE /case/createsprint HTTP/1.1" 500 210291
[2023-12-19 12:02:23,831] [basehttp.py:187] [basehttp:log_message] [INFO]- "OPTIONS /case/updatesprint HTTP/1.1" 200 0
[2023-12-19 12:02:23,849] [basehttp.py:187] [basehttp:log_message] [INFO]- "POST /case/updatesprint HTTP/1.1" 200 36
[2023-12-19 12:02:23,988] [basehttp.py:187] [basehttp:log_message] [INFO]- "POST /case/sprintlist HTTP/1.1" 200 46
[2023-12-19 12:02:26,483] [log.py:241] [log:log_response] [ERROR]- Internal Server Error: /case/createsprint
Traceback (most recent call last):
  File "/Users/yehl/Documents/软件测试资料/softwarebox/lib/python3.10/site-packages/django/db/backends/utils.py", line 89, in _execute
    return self.cursor.execute(sql, params)
  File "/Users/yehl/Documents/软件测试资料/softwarebox/lib/python3.10/site-packages/django/db/backends/mysql/base.py", line 75, in execute
    return self.cursor.execute(query, args)
  File "/Users/yehl/Documents/软件测试资料/softwarebox/lib/python3.10/site-packages/pymysql/cursors.py", line 148, in execute
    result = self._query(query)
  File "/Users/yehl/Documents/软件测试资料/softwarebox/lib/python3.10/site-packages/pymysql/cursors.py", line 310, in _query
    conn.query(q)
  File "/Users/yehl/Documents/软件测试资料/softwarebox/lib/python3.10/site-packages/pymysql/connections.py", line 548, in query
    self._affected_rows = self._read_query_result(unbuffered=unbuffered)
  File "/Users/yehl/Documents/软件测试资料/softwarebox/lib/python3.10/site-packages/pymysql/connections.py", line 775, in _read_query_result
    result.read()
  File "/Users/yehl/Documents/软件测试资料/softwarebox/lib/python3.10/site-packages/pymysql/connections.py", line 1156, in read
    first_packet = self.connection._read_packet()
  File "/Users/yehl/Documents/软件测试资料/softwarebox/lib/python3.10/site-packages/pymysql/connections.py", line 725, in _read_packet
    packet.raise_for_error()
  File "/Users/yehl/Documents/软件测试资料/softwarebox/lib/python3.10/site-packages/pymysql/protocol.py", line 221, in raise_for_error
    err.raise_mysql_exception(self._data)
  File "/Users/yehl/Documents/软件测试资料/softwarebox/lib/python3.10/site-packages/pymysql/err.py", line 143, in raise_mysql_exception
    raise errorclass(errno, errval)
pymysql.err.ProgrammingError: (1146, "Table 'testplatform.apiauto_apiauto' doesn't exist")

The above exception was the direct cause of the following exception:

Traceback (most recent call last):
  File "/Users/yehl/Documents/软件测试资料/softwarebox/lib/python3.10/site-packages/django/core/handlers/exception.py", line 55, in inner
    response = get_response(request)
  File "/Users/yehl/Documents/软件测试资料/softwarebox/lib/python3.10/site-packages/django/core/handlers/base.py", line 197, in _get_response
    response = wrapped_callback(request, *callback_args, **callback_kwargs)
  File "/Users/yehl/Documents/软件测试资料/softwarebox/lib/python3.10/site-packages/django/views/decorators/csrf.py", line 54, in wrapped_view
    return view_func(*args, **kwargs)
  File "/Users/yehl/Documents/软件测试资料/softwarebox/lib/python3.10/site-packages/django/views/generic/base.py", line 84, in view
    return self.dispatch(request, *args, **kwargs)
  File "/Users/yehl/Documents/软件测试资料/softwarebox/lib/python3.10/site-packages/rest_framework/views.py", line 509, in dispatch
    response = self.handle_exception(exc)
  File "/Users/yehl/Documents/软件测试资料/softwarebox/lib/python3.10/site-packages/rest_framework/views.py", line 469, in handle_exception
    self.raise_uncaught_exception(exc)
  File "/Users/yehl/Documents/软件测试资料/softwarebox/lib/python3.10/site-packages/rest_framework/views.py", line 480, in raise_uncaught_exception
    raise exc
  File "/Users/yehl/Documents/软件测试资料/softwarebox/lib/python3.10/site-packages/rest_framework/views.py", line 506, in dispatch
    response = handler(request, *args, **kwargs)
  File "/Users/yehl/Documents/testPlaform/TPlatform/SprintList/views.py", line 36, in delete
    sprints.objects.get(sprint_name=sprint_name).delete()
  File "/Users/yehl/Documents/软件测试资料/softwarebox/lib/python3.10/site-packages/django/db/models/base.py", line 1094, in delete
    return collector.delete()
  File "/Users/yehl/Documents/软件测试资料/softwarebox/lib/python3.10/site-packages/django/db/models/deletion.py", line 462, in delete
    count = qs._raw_delete(using=self.using)
  File "/Users/yehl/Documents/软件测试资料/softwarebox/lib/python3.10/site-packages/django/db/models/query.py", line 843, in _raw_delete
    cursor = query.get_compiler(using).execute_sql(CURSOR)
  File "/Users/yehl/Documents/软件测试资料/softwarebox/lib/python3.10/site-packages/django/db/models/sql/compiler.py", line 1361, in execute_sql
    cursor.execute(sql, params)
  File "/Users/yehl/Documents/软件测试资料/softwarebox/lib/python3.10/site-packages/django/db/backends/utils.py", line 103, in execute
    return super().execute(sql, params)
  File "/Users/yehl/Documents/软件测试资料/softwarebox/lib/python3.10/site-packages/django/db/backends/utils.py", line 67, in execute
    return self._execute_with_wrappers(
  File "/Users/yehl/Documents/软件测试资料/softwarebox/lib/python3.10/site-packages/django/db/backends/utils.py", line 80, in _execute_with_wrappers
    return executor(sql, params, many, context)
  File "/Users/yehl/Documents/软件测试资料/softwarebox/lib/python3.10/site-packages/django/db/backends/utils.py", line 84, in _execute
    with self.db.wrap_database_errors:
  File "/Users/yehl/Documents/软件测试资料/softwarebox/lib/python3.10/site-packages/django/db/utils.py", line 91, in __exit__
    raise dj_exc_value.with_traceback(traceback) from exc_value
  File "/Users/yehl/Documents/软件测试资料/softwarebox/lib/python3.10/site-packages/django/db/backends/utils.py", line 89, in _execute
    return self.cursor.execute(sql, params)
  File "/Users/yehl/Documents/软件测试资料/softwarebox/lib/python3.10/site-packages/django/db/backends/mysql/base.py", line 75, in execute
    return self.cursor.execute(query, args)
  File "/Users/yehl/Documents/软件测试资料/softwarebox/lib/python3.10/site-packages/pymysql/cursors.py", line 148, in execute
    result = self._query(query)
  File "/Users/yehl/Documents/软件测试资料/softwarebox/lib/python3.10/site-packages/pymysql/cursors.py", line 310, in _query
    conn.query(q)
  File "/Users/yehl/Documents/软件测试资料/softwarebox/lib/python3.10/site-packages/pymysql/connections.py", line 548, in query
    self._affected_rows = self._read_query_result(unbuffered=unbuffered)
  File "/Users/yehl/Documents/软件测试资料/softwarebox/lib/python3.10/site-packages/pymysql/connections.py", line 775, in _read_query_result
    result.read()
  File "/Users/yehl/Documents/软件测试资料/softwarebox/lib/python3.10/site-packages/pymysql/connections.py", line 1156, in read
    first_packet = self.connection._read_packet()
  File "/Users/yehl/Documents/软件测试资料/softwarebox/lib/python3.10/site-packages/pymysql/connections.py", line 725, in _read_packet
    packet.raise_for_error()
  File "/Users/yehl/Documents/软件测试资料/softwarebox/lib/python3.10/site-packages/pymysql/protocol.py", line 221, in raise_for_error
    err.raise_mysql_exception(self._data)
  File "/Users/yehl/Documents/软件测试资料/softwarebox/lib/python3.10/site-packages/pymysql/err.py", line 143, in raise_mysql_exception
    raise errorclass(errno, errval)
django.db.utils.ProgrammingError: (1146, "Table 'testplatform.apiauto_apiauto' doesn't exist")
[2023-12-19 12:02:26,490] [basehttp.py:187] [basehttp:log_message] [ERROR]- "DELETE /case/createsprint HTTP/1.1" 500 210291
[2023-12-19 12:02:28,545] [basehttp.py:187] [basehttp:log_message] [INFO]- "POST /case/sprintlist HTTP/1.1" 200 46
[2023-12-19 12:02:33,865] [basehttp.py:187] [basehttp:log_message] [INFO]- "POST /case/sprintlist HTTP/1.1" 200 46
[2023-12-19 12:02:59,428] [basehttp.py:187] [basehttp:log_message] [INFO]- "POST /case/createsprint HTTP/1.1" 200 36
[2023-12-19 12:03:00,897] [basehttp.py:187] [basehttp:log_message] [INFO]- "POST /case/sprintlist HTTP/1.1" 200 116
[2023-12-19 12:03:21,996] [basehttp.py:187] [basehttp:log_message] [INFO]- "POST /case/createsprint HTTP/1.1" 200 36
[2023-12-19 12:03:23,163] [basehttp.py:187] [basehttp:log_message] [INFO]- "POST /case/sprintlist HTTP/1.1" 200 192
[2023-12-19 12:03:33,017] [basehttp.py:187] [basehttp:log_message] [INFO]- "POST /case/sprintlist HTTP/1.1" 200 192
[2023-12-19 12:03:37,089] [basehttp.py:187] [basehttp:log_message] [INFO]- "POST /case/sprintlist HTTP/1.1" 200 192
[2023-12-19 12:03:40,657] [basehttp.py:187] [basehttp:log_message] [INFO]- "POST /case/updatesprint HTTP/1.1" 200 36
[2023-12-19 12:03:40,788] [basehttp.py:187] [basehttp:log_message] [INFO]- "POST /case/sprintlist HTTP/1.1" 200 192
[2023-12-19 12:04:33,593] [basehttp.py:187] [basehttp:log_message] [INFO]- "OPTIONS /case/sprintlist HTTP/1.1" 200 0
[2023-12-19 12:04:33,596] [log.py:241] [log:log_response] [WARNING]- Forbidden: /case/sprintlist
[2023-12-19 12:04:33,597] [basehttp.py:187] [basehttp:log_message] [WARNING]- "POST /case/sprintlist HTTP/1.1" 403 28
[2023-12-19 12:04:36,819] [basehttp.py:187] [basehttp:log_message] [INFO]- "POST /group/login HTTP/1.1" 200 136
[2023-12-19 12:04:40,104] [basehttp.py:187] [basehttp:log_message] [INFO]- "POST /case/sprintlist HTTP/1.1" 200 192
[2023-12-19 12:04:43,377] [basehttp.py:187] [basehttp:log_message] [INFO]- "OPTIONS /case/count_case HTTP/1.1" 200 0
[2023-12-19 12:04:43,387] [basehttp.py:187] [basehttp:log_message] [INFO]- "OPTIONS /case/caselist/%E8%BF%AD%E4%BB%A31 HTTP/1.1" 200 0
[2023-12-19 12:04:43,395] [basehttp.py:187] [basehttp:log_message] [INFO]- "POST /case/count_case HTTP/1.1" 200 63
[2023-12-19 12:04:43,400] [basehttp.py:187] [basehttp:log_message] [INFO]- "POST /case/caselist/%E8%BF%AD%E4%BB%A31 HTTP/1.1" 200 1544
[2023-12-19 12:04:47,044] [basehttp.py:187] [basehttp:log_message] [INFO]- "POST /case/sprintlist HTTP/1.1" 200 192
[2023-12-19 12:06:06,239] [basehttp.py:187] [basehttp:log_message] [INFO]- "POST /case/caselist/%E8%BF%AD%E4%BB%A31 HTTP/1.1" 200 1544
[2023-12-19 12:06:06,244] [basehttp.py:187] [basehttp:log_message] [INFO]- "POST /case/count_case HTTP/1.1" 200 63
[2023-12-19 12:10:51,416] [basehttp.py:187] [basehttp:log_message] [INFO]- "POST /case/sprintlist HTTP/1.1" 200 211
[2023-12-19 12:58:50,301] [autoreload.py:266] [autoreload:trigger_reload] [INFO]- /Users/yehl/Documents/testPlaform/TPlatform/TPlatform/TokenAuth.py changed, reloading.
[2023-12-19 12:58:50,662] [autoreload.py:677] [autoreload:run_with_reloader] [INFO]- Watching for file changes with StatReloader
[2023-12-19 13:00:58,183] [basehttp.py:187] [basehttp:log_message] [INFO]- "OPTIONS /case/count_case HTTP/1.1" 200 0
[2023-12-19 13:00:58,183] [basehttp.py:187] [basehttp:log_message] [INFO]- "OPTIONS /case/caselist/%E8%BF%AD%E4%BB%A31 HTTP/1.1" 200 0
[2023-12-19 13:01:10,944] [basehttp.py:187] [basehttp:log_message] [INFO]- "POST /group/login HTTP/1.1" 200 136
[2023-12-19 13:01:16,106] [basehttp.py:187] [basehttp:log_message] [INFO]- "OPTIONS /case/sprintlist HTTP/1.1" 200 0
[2023-12-19 13:01:19,152] [basehttp.py:187] [basehttp:log_message] [INFO]- "POST /group/login HTTP/1.1" 200 136
[2023-12-19 13:01:21,902] [basehttp.py:187] [basehttp:log_message] [INFO]- "OPTIONS /case/sprintlist HTTP/1.1" 200 0
[2023-12-19 13:03:00,066] [basehttp.py:187] [basehttp:log_message] [INFO]- "OPTIONS /case/sprintlist HTTP/1.1" 200 0
[2023-12-19 13:03:02,823] [basehttp.py:187] [basehttp:log_message] [INFO]- "POST /group/login HTTP/1.1" 200 136
[2023-12-19 13:03:05,873] [basehttp.py:187] [basehttp:log_message] [INFO]- "OPTIONS /case/sprintlist HTTP/1.1" 200 0
[2023-12-19 13:03:28,267] [autoreload.py:266] [autoreload:trigger_reload] [INFO]- /Users/yehl/Documents/testPlaform/TPlatform/TPlatform/TokenAuth.py changed, reloading.
[2023-12-19 13:03:28,539] [autoreload.py:677] [autoreload:run_with_reloader] [INFO]- Watching for file changes with StatReloader
[2023-12-19 13:04:26,990] [autoreload.py:266] [autoreload:trigger_reload] [INFO]- /Users/yehl/Documents/testPlaform/TPlatform/TPlatform/TokenAuth.py changed, reloading.
[2023-12-19 13:04:27,261] [autoreload.py:677] [autoreload:run_with_reloader] [INFO]- Watching for file changes with StatReloader
[2023-12-19 13:04:31,635] [basehttp.py:187] [basehttp:log_message] [INFO]- "POST /group/login HTTP/1.1" 200 136
[2023-12-19 13:04:33,907] [basehttp.py:187] [basehttp:log_message] [INFO]- "OPTIONS /case/sprintlist HTTP/1.1" 200 0
[2023-12-19 13:04:46,901] [autoreload.py:266] [autoreload:trigger_reload] [INFO]- /Users/yehl/Documents/testPlaform/TPlatform/TPlatform/TokenAuth.py changed, reloading.
[2023-12-19 13:04:47,141] [autoreload.py:677] [autoreload:run_with_reloader] [INFO]- Watching for file changes with StatReloader
[2023-12-19 13:04:58,188] [basehttp.py:187] [basehttp:log_message] [INFO]- "POST /group/login HTTP/1.1" 200 136
[2023-12-19 13:05:00,476] [basehttp.py:187] [basehttp:log_message] [INFO]- "OPTIONS /case/sprintlist HTTP/1.1" 200 0
[2023-12-19 13:05:00,483] [basehttp.py:187] [basehttp:log_message] [INFO]- "POST /case/sprintlist HTTP/1.1" 200 211
[2023-12-19 13:07:01,917] [log.py:241] [log:log_response] [WARNING]- Forbidden: /case/sprintlist
[2023-12-19 13:07:01,918] [basehttp.py:187] [basehttp:log_message] [WARNING]- "POST /case/sprintlist HTTP/1.1" 403 28
[2023-12-19 13:09:08,456] [log.py:241] [log:log_response] [WARNING]- Forbidden: /case/sprintlist
[2023-12-19 13:09:08,457] [basehttp.py:187] [basehttp:log_message] [WARNING]- "POST /case/sprintlist HTTP/1.1" 403 28
[2023-12-19 13:10:01,583] [log.py:241] [log:log_response] [WARNING]- Forbidden: /case/sprintlist
[2023-12-19 13:10:01,586] [basehttp.py:187] [basehttp:log_message] [WARNING]- "POST /case/sprintlist HTTP/1.1" 403 28
[2023-12-19 13:10:07,546] [log.py:241] [log:log_response] [WARNING]- Forbidden: /case/sprintlist
[2023-12-19 13:10:07,547] [basehttp.py:187] [basehttp:log_message] [WARNING]- "POST /case/sprintlist HTTP/1.1" 403 28
[2023-12-19 13:11:20,688] [log.py:241] [log:log_response] [WARNING]- Forbidden: /case/sprintlist
[2023-12-19 13:11:20,692] [basehttp.py:187] [basehttp:log_message] [WARNING]- "POST /case/sprintlist HTTP/1.1" 403 28
[2023-12-19 13:11:52,834] [log.py:241] [log:log_response] [WARNING]- Forbidden: /case/sprintlist
[2023-12-19 13:11:52,834] [basehttp.py:187] [basehttp:log_message] [WARNING]- "POST /case/sprintlist HTTP/1.1" 403 28
[2023-12-19 13:27:20,254] [log.py:241] [log:log_response] [WARNING]- Forbidden: /case/sprintlist
[2023-12-19 13:27:20,256] [basehttp.py:187] [basehttp:log_message] [WARNING]- "POST /case/sprintlist HTTP/1.1" 403 28
[2023-12-19 13:27:30,297] [log.py:241] [log:log_response] [WARNING]- Forbidden: /case/sprintlist
[2023-12-19 13:27:30,298] [basehttp.py:187] [basehttp:log_message] [WARNING]- "POST /case/sprintlist HTTP/1.1" 403 28
[2023-12-19 13:27:52,747] [log.py:241] [log:log_response] [WARNING]- Forbidden: /case/sprintlist
[2023-12-19 13:27:52,749] [basehttp.py:187] [basehttp:log_message] [WARNING]- "POST /case/sprintlist HTTP/1.1" 403 28
[2023-12-19 13:28:12,234] [log.py:241] [log:log_response] [WARNING]- Forbidden: /case/sprintlist
[2023-12-19 13:28:12,235] [basehttp.py:187] [basehttp:log_message] [WARNING]- "POST /case/sprintlist HTTP/1.1" 403 28
[2023-12-19 13:29:04,529] [basehttp.py:187] [basehttp:log_message] [INFO]- "POST /group/login HTTP/1.1" 200 135
[2023-12-19 13:29:07,539] [basehttp.py:187] [basehttp:log_message] [INFO]- "POST /group/login HTTP/1.1" 200 135
[2023-12-19 13:29:24,002] [basehttp.py:187] [basehttp:log_message] [INFO]- "POST /case/sprintlist HTTP/1.1" 200 211
[2023-12-19 13:30:03,971] [basehttp.py:187] [basehttp:log_message] [INFO]- "POST /case/sprintlist HTTP/1.1" 200 211
[2023-12-19 15:38:23,596] [basehttp.py:187] [basehttp:log_message] [INFO]- "POST /group/login HTTP/1.1" 200 135
[2023-12-19 15:50:51,098] [basehttp.py:187] [basehttp:log_message] [INFO]- "POST /group/login HTTP/1.1" 200 135
[2023-12-19 15:52:17,994] [basehttp.py:187] [basehttp:log_message] [INFO]- "POST /group/login HTTP/1.1" 200 135
[2023-12-19 15:57:58,225] [basehttp.py:187] [basehttp:log_message] [INFO]- "POST /group/login HTTP/1.1" 200 135
[2023-12-19 15:58:21,465] [basehttp.py:187] [basehttp:log_message] [INFO]- "POST /group/login HTTP/1.1" 200 131
[2023-12-19 15:59:06,761] [log.py:241] [log:log_response] [WARNING]- Forbidden: /case/sprintlist
[2023-12-19 15:59:06,763] [basehttp.py:187] [basehttp:log_message] [WARNING]- "POST /case/sprintlist HTTP/1.1" 403 28
[2023-12-19 15:59:27,088] [basehttp.py:187] [basehttp:log_message] [INFO]- "POST /case/sprintlist HTTP/1.1" 200 211
[2023-12-19 16:00:45,011] [basehttp.py:187] [basehttp:log_message] [INFO]- "POST /case/sprintlist HTTP/1.1" 200 211
[2023-12-19 16:00:55,482] [basehttp.py:187] [basehttp:log_message] [INFO]- "POST /case/sprintlist HTTP/1.1" 200 211
[2023-12-19 16:01:11,934] [basehttp.py:187] [basehttp:log_message] [INFO]- "POST /case/sprintlist HTTP/1.1" 200 211
[2023-12-19 16:01:21,692] [basehttp.py:187] [basehttp:log_message] [INFO]- "POST /case/sprintlist HTTP/1.1" 200 211
[2023-12-19 16:01:54,654] [basehttp.py:187] [basehttp:log_message] [INFO]- "POST /case/sprintlist HTTP/1.1" 200 211
[2023-12-19 16:02:34,700] [basehttp.py:187] [basehttp:log_message] [INFO]- "POST /case/sprintlist HTTP/1.1" 200 211
[2023-12-19 16:02:47,309] [basehttp.py:187] [basehttp:log_message] [INFO]- "POST /case/sprintlist HTTP/1.1" 200 211
[2023-12-19 16:03:17,465] [basehttp.py:187] [basehttp:log_message] [INFO]- "POST /case/sprintlist HTTP/1.1" 200 211
[2023-12-19 17:00:18,813] [basehttp.py:187] [basehttp:log_message] [INFO]- "POST /group/login HTTP/1.1" 200 135
[2023-12-19 17:02:23,245] [basehttp.py:187] [basehttp:log_message] [INFO]- "POST /group/login HTTP/1.1" 200 135
[2023-12-19 17:07:37,120] [basehttp.py:187] [basehttp:log_message] [INFO]- "POST /case/sprintlist HTTP/1.1" 200 211
[2023-12-19 17:07:56,397] [basehttp.py:187] [basehttp:log_message] [INFO]- "POST /case/sprintlist HTTP/1.1" 200 211
[2023-12-19 17:23:25,204] [basehttp.py:187] [basehttp:log_message] [INFO]- "POST /group/login HTTP/1.1" 200 135
[2023-12-19 17:25:40,876] [basehttp.py:187] [basehttp:log_message] [INFO]- "POST /group/login HTTP/1.1" 200 135
[2023-12-20 11:06:28,286] [log.py:241] [log:log_response] [WARNING]- Bad Request: /case/sprintlist
[2023-12-20 11:06:28,287] [basehttp.py:187] [basehttp:log_message] [WARNING]- "POST /case/sprintlist HTTP/1.1" 400 109
[2023-12-20 11:07:05,765] [basehttp.py:187] [basehttp:log_message] [INFO]- "POST /group/login HTTP/1.1" 200 135
[2023-12-20 11:07:45,797] [log.py:241] [log:log_response] [WARNING]- Bad Request: /case/sprintlist
[2023-12-20 11:07:45,799] [basehttp.py:187] [basehttp:log_message] [WARNING]- "POST /case/sprintlist HTTP/1.1" 400 75
[2023-12-20 11:08:21,832] [log.py:241] [log:log_response] [WARNING]- Forbidden: /case/sprintlist
[2023-12-20 11:08:21,832] [basehttp.py:187] [basehttp:log_message] [WARNING]- "POST /case/sprintlist HTTP/1.1" 403 28
[2023-12-20 11:08:29,085] [basehttp.py:187] [basehttp:log_message] [INFO]- "POST /group/login HTTP/1.1" 200 135
[2023-12-20 11:08:31,627] [log.py:241] [log:log_response] [WARNING]- Forbidden: /case/sprintlist
[2023-12-20 11:08:31,628] [basehttp.py:187] [basehttp:log_message] [WARNING]- "POST /case/sprintlist HTTP/1.1" 403 28
[2023-12-20 11:09:11,012] [basehttp.py:187] [basehttp:log_message] [INFO]- "POST /case/sprintlist HTTP/1.1" 200 211
[2023-12-20 11:13:16,462] [basehttp.py:187] [basehttp:log_message] [INFO]- "POST /group/login HTTP/1.1" 200 135
[2023-12-20 11:13:22,445] [basehttp.py:187] [basehttp:log_message] [INFO]- "POST /case/sprintlist HTTP/1.1" 200 211
